<?xml version="1.0"?>
<!-- =================================================================================== -->
<!-- |    This document was autogenerated by xacro from /home/omotoye/catkin_ws/src/cluerosity/cluerosity_description/urdf/cluerosity_manipulator.xacro | -->
<!-- |    EDITING THIS FILE BY HAND IS NOT RECOMMENDED                                 | -->
<!-- =================================================================================== -->
<robot name="cluerosity_manipulator">
    <material name="black">
        <color rgba="0.0 0.0 0.0 1.0" />
    </material>
    <material name="blue">
        <color rgba="0.203125 0.23828125 0.28515625 1.0" />
    </material>
    <material name="green">
        <color rgba="0.0 0.8 0.0 1.0" />
    </material>
    <material name="grey">
        <color rgba="0.2 0.2 0.2 1.0" />
    </material>
    <material name="orange">
        <color rgba="1.0 0.423529411765 0.0392156862745 1.0" />
    </material>
    <material name="brown">
        <color rgba="0.870588235294 0.811764705882 0.764705882353 1.0" />
    </material>
    <material name="red">
        <color rgba="0.80078125 0.12890625 0.1328125 1.0" />
    </material>
    <material name="white">
        <color rgba="1.0 1.0 1.0 1.0" />
    </material>
    <material name="dark_gray">
        <color rgba="0.35 0.38 0.4 1" />
    </material>
    <material name="cyan">
        <color rgba="0 1.0 1.0 1.0" />
    </material>
    <!-- 
        +==================================+
        |      Wheel Definition Macro      |
        +=================================+ 
    -->
    <!-- 
        +=============================+
        |      Wheel Shaft Macro      |
        +============================+ 
    -->
    <!-- 
        +===========================+
        |      Fixed Link Macro     |
        +==========================+ 
    -->
    <!-- 
        +===========================+
        |   Continuous Link Macro    |
        +==========================+ 
    -->
    <!-- 
        +===========================+
        |  Revolute Link Macro    |
        +==========================+ 
    -->
    <!-- 
        +==============================================+
        |      Base Link and Base footprint Macro      |
        +==============================================+ 
    -->
    <!-- 
        +==================================+
        |   Sensor Gimbal links Macro     |
        +================================+ 
    -->
    <gazebo reference="gimbal_base">
        <material>Gazebo/DarkGrey</material>
    </gazebo>
    <gazebo>
        <plugin filename="libgazebo_ros_skid_steer_drive.so" name="skid_steer_drive_controller">
            <updateRate>20.0</updateRate>
            <robotNamespace>/</robotNamespace>
            <leftFrontJoint>left_front_wheel_joint</leftFrontJoint>
            <rightFrontJoint>right_front_wheel_joint</rightFrontJoint>
            <leftRearJoint>left_rear_wheel_joint</leftRearJoint>
            <rightRearJoint>right_rear_wheel_joint</rightRearJoint>
            <wheelSeparation>0.6</wheelSeparation>
            <wheelDiameter>0.33</wheelDiameter>
            <robotBaseFrame>base_footprint</robotBaseFrame>
            <torque>10000</torque>
            <topicName>cmd_vel</topicName>
            <broadcastTF>true</broadcastTF>
            <odometryTopic>odom</odometryTopic>
            <odometryFrame>odom</odometryFrame>
        </plugin>
    </gazebo>
    <!-- ros_control plugin -->
    <gazebo>
        <plugin filename="libgazebo_ros_control.so" name="gazebo_ros_control">
            <robotNamespace>cluerosity</robotNamespace>
            <robotSimType>gazebo_ros_control/DefaultRobotHWSim</robotSimType>
            <legacyModeNS>true</legacyModeNS>
        </plugin>
    </gazebo>
    <!-- hokuyo -->
    <gazebo reference="hokuyo_link">
        <sensor name="head_hokuyo_sensor" type="gpu_ray">
            <pose>0 0 0 0 0 0</pose>
            <visualize>false</visualize>
            <update_rate>40</update_rate>
            <ray>
                <scan>
                    <horizontal>
                        <samples>720</samples>
                        <resolution>1</resolution>
                        <min_angle>-1.570796</min_angle>
                        <max_angle>1.570796</max_angle>
                    </horizontal>
                </scan>
                <range>
                    <min>0.10</min>
                    <max>30.0</max>
                    <resolution>0.01</resolution>
                </range>
                <noise>
                    <type>gaussian</type>
                    <!-- Noise parameters based on published spec for Hokuyo laser
               achieving "+-30mm" accuracy at range < 10m.  A mean of 0.0m and
               stddev of 0.01m will put 99.7% of samples within 0.03m of the true
               reading. -->
                    <mean>0.0</mean>
                    <stddev>0.01</stddev>
                </noise>
            </ray>
            <plugin filename="libgazebo_ros_gpu_laser.so" name="gazebo_ros_head_hokuyo_controller">
                <topicName>laser_scan</topicName>
                <frameName>hokuyo_link</frameName>
            </plugin>
        </sensor>
    </gazebo>
    <!-- camera -->
    <gazebo reference="camera_link">
        <sensor name="camera1" type="camera">
            <update_rate>30.0</update_rate>
            <camera name="head">
                <horizontal_fov>1.3962634</horizontal_fov>
                <image>
                    <width>800</width>
                    <height>800</height>
                    <format>R8G8B8</format>
                </image>
                <clip>
                    <near>0.02</near>
                    <far>300</far>
                </clip>
                <noise>
                    <type>gaussian</type>
                    <!-- Noise is sampled independently per pixel on each frame.
               That pixel's noise value is added to each of its color
               channels, which at that point lie in the range [0,1]. -->
                    <mean>0.0</mean>
                    <stddev>0.007</stddev>
                </noise>
            </camera>
            <plugin filename="libgazebo_ros_camera.so" name="camera_controller">
                <alwaysOn>true</alwaysOn>
                <updateRate>0.0</updateRate>
                <cameraName>cluerosity/camera1</cameraName>
                <imageTopicName>image_raw</imageTopicName>
                <cameraInfoTopicName>camera_info</cameraInfoTopicName>
                <frameName>camera_link</frameName>
                <hackBaseline>0.07</hackBaseline>
                <distortionK1>0.0</distortionK1>
                <distortionK2>0.0</distortionK2>
                <distortionK3>0.0</distortionK3>
                <distortionT1>0.0</distortionT1>
                <distortionT2>0.0</distortionT2>
            </plugin>
        </sensor>
    </gazebo>
    <!-- rgbd -->
    <gazebo reference="camera_link">
        <sensor name="rgbd" type="depth">
            <update_rate>20</update_rate>
            <camera>
                <horizontal_fov>1.047198</horizontal_fov>
                <image>
                    <width>640</width>
                    <height>480</height>
                    <format>R8G8B8</format>
                </image>
                <clip>
                    <near>0.05</near>
                    <far>3</far>
                </clip>
            </camera>
            <plugin filename="libgazebo_ros_openni_kinect.so" name="camera_controller">
                <baseline>0.2</baseline>
                <alwaysOn>true</alwaysOn>
                <updateRate>1.0</updateRate>
                <cameraName>camera_ir</cameraName>
                <imageTopicName>/camera/color/image_raw</imageTopicName>
                <cameraInfoTopicName>/camera/color/camera_info</cameraInfoTopicName>
                <depthImageTopicName>/camera/depth/image_raw</depthImageTopicName>
                <depthImageInfoTopicName>/camera/depth/camera_info</depthImageInfoTopicName>
                <pointCloudTopicName>/camera/depth/points</pointCloudTopicName>
                <frameName>camera_depth_link</frameName>
                <pointCloudCutoff>0.5</pointCloudCutoff>
                <pointCloudCutoffMax>3.0</pointCloudCutoffMax>
                <distortionK1>0.00000001</distortionK1>
                <distortionK2>0.00000001</distortionK2>
                <distortionK3>0.00000001</distortionK3>
                <distortionT1>0.00000001</distortionT1>
                <distortionT2>0.00000001</distortionT2>
                <CxPrime>0</CxPrime>
                <Cx>0</Cx>
                <Cy>0</Cy>
                <focalLength>0</focalLength>
                <hackBaseline>0</hackBaseline>
            </plugin>
        </sensor>
    </gazebo>
    <link name="base_link">
        <visual>
            <origin rpy="0 3.14159265359 -1.570796326795" xyz="0 0 0.15" />
            <geometry>
                <mesh filename="package://cluerosity_description/meshes/robot_base.dae" />
            </geometry>
        </visual>
        <collision>
            <origin rpy="0 0 0" xyz="0 0 0.075" />
            <geometry>
                <box size="0.8 0.4 0.15" />
            </geometry>
        </collision>
        <collision>
            <origin rpy="0 0 0" xyz="-0.325 0.14 0.2" />
            <geometry>
                <box size="0.15 0.12 0.1" />
            </geometry>
        </collision>
        <collision>
            <origin rpy="0 0 0" xyz="0.45 0.1 0.05" />
            <geometry>
                <box size="0.1 0.1 0.05" />
            </geometry>
        </collision>

        <inertial>
            <mass value="56.77662104" />
            <origin rpy="0 0 0" xyz="0 0 0.075" />
            <inertia ixx="2.64" ixy="0.221" ixz="0.046" iyy="0.907" iyz="-0.237" izz="3.303" />
        </inertial>

    </link>
    <!-- Base footprint is on the ground under the robot -->
    <link name="base_footprint" />
    <joint name="base_link_joint" type="fixed">
        <origin rpy="0 0 0" xyz="0 0 0.115" />
        <parent link="base_footprint" />
        <child link="base_link" />
    </joint>
    <link name="front_shaft">
        <visual>
            <origin rpy="1.570796326795 0 0" xyz="0 0 0" />
            <geometry>
                <cylinder length="0.55" radius="0.01" />
            </geometry>
            <material name="white" />
        </visual>
        <collision>
            <origin rpy="1.570796326795 0 0" xyz="0 0 0" />
            <geometry>
                <cylinder length="0.55" radius="0.01" />
            </geometry>
        </collision>

        <inertial>
            <mass value="0.30129837" />
            <origin rpy="1.570796326795 0 0" xyz="0 0 0" />
            <inertia ixx="0.00759711" ixy="0" ixz="0" iyy="0.00759711" iyz="0" izz="3.77e-06" />
        </inertial>

    </link>
    <joint name="front_shaft_joint" type="fixed">
        <parent link="base_link" />
        <child link="front_shaft" />
        <origin rpy="0 0 0" xyz="0.350 0 0.05" />
    </joint>
    <link name="rear_shaft">
        <visual>
            <origin rpy="1.570796326795 0 0" xyz="0 0 0" />
            <geometry>
                <cylinder length="0.55" radius="0.01" />
            </geometry>
            <material name="white" />
        </visual>
        <collision>
            <origin rpy="1.570796326795 0 0" xyz="0 0 0" />
            <geometry>
                <cylinder length="0.55" radius="0.01" />
            </geometry>
        </collision>

        <inertial>
            <mass value="0.30129837" />
            <origin rpy="1.570796326795 0 0" xyz="0 0 0" />
            <inertia ixx="0.00759711" ixy="0" ixz="0" iyy="0.00759711" iyz="0" izz="3.77e-06" />
        </inertial>

    </link>
    <joint name="rear_shaft_joint" type="fixed">
        <parent link="base_link" />
        <child link="rear_shaft" />
        <origin rpy="0 0 0" xyz="-0.20 0 0.05" />
    </joint>
    <!-- 
        +=====================+
        |   Wheel definition  |
        +=====================+ 
    -->
    <link name="right_front_wheel">
        <visual>
            <origin rpy="1.570796326795 0 -1.570796326795" xyz="-0.14686986 0 0" />
            <geometry>
                <mesh filename="package://cluerosity_description/meshes/tyre.dae" />
            </geometry>
        </visual>
        <visual>
            <origin rpy="0 0 0" xyz="0 0 0" />
            <geometry>
                <mesh filename="package://cluerosity_description/meshes/rim.dae" />
            </geometry>
        </visual>
        <collision>
            <origin rpy="1.570796326795 0 0" xyz="0 0 0" />
            <geometry>
                <cylinder length="0.15" radius="0.165" />
            </geometry>
        </collision>

        <inertial>
            <mass value="5.52250093" />
            <origin rpy="1.570796326795 0 0" xyz="0 0 0" />
            <inertia ixx="0.13326254" ixy="0" ixz="0" iyy="0.07660474" iyz="0" izz="0.077" />
        </inertial>

    </link>
    <joint name="right_front_wheel_joint" type="continuous">
        <parent link="base_link" />
        <child link="right_front_wheel" />
        <origin rpy="0 0 0" xyz="0.35 -0.30 0.05" />
        <axis rpy="0 0 0" xyz="0 1 0" />
    </joint>
    <link name="right_rear_wheel">
        <visual>
            <origin rpy="1.570796326795 0 -1.570796326795" xyz="-0.14686986 0 0" />
            <geometry>
                <mesh filename="package://cluerosity_description/meshes/tyre.dae" />
            </geometry>
        </visual>
        <visual>
            <origin rpy="0 0 0" xyz="0 0 0" />
            <geometry>
                <mesh filename="package://cluerosity_description/meshes/rim.dae" />
            </geometry>
        </visual>
        <collision>
            <origin rpy="1.570796326795 0 0" xyz="0 0 0" />
            <geometry>
                <cylinder length="0.15" radius="0.165" />
            </geometry>
        </collision>

        <inertial>
            <mass value="5.52250093" />
            <origin rpy="1.570796326795 0 0" xyz="0 0 0" />
            <inertia ixx="0.13326254" ixy="0" ixz="0" iyy="0.07660474" iyz="0" izz="0.077" />
        </inertial>

    </link>
    <joint name="right_rear_wheel_joint" type="continuous">
        <parent link="base_link" />
        <child link="right_rear_wheel" />
        <origin rpy="0 0 0" xyz="-0.20 -0.30 0.05" />
        <axis rpy="0 0 0" xyz="0 1 0" />
    </joint>
    <link name="left_front_wheel">
        <visual>
            <origin rpy="1.570796326795 0 -1.570796326795" xyz="-0.14686986 0 0" />
            <geometry>
                <mesh filename="package://cluerosity_description/meshes/tyre.dae" />
            </geometry>
        </visual>
        <visual>
            <origin rpy="0 0 3.14159265359" xyz="0 0 0" />
            <geometry>
                <mesh filename="package://cluerosity_description/meshes/rim.dae" />
            </geometry>
        </visual>
        <collision>
            <origin rpy="1.570796326795 0 0" xyz="0 0 0" />
            <geometry>
                <cylinder length="0.15" radius="0.165" />
            </geometry>
        </collision>

        <inertial>
            <mass value="5.52250093" />
            <origin rpy="1.570796326795 0 0" xyz="0 0 0" />
            <inertia ixx="0.13326254" ixy="0" ixz="0" iyy="0.07660474" iyz="0" izz="0.077" />
        </inertial>

    </link>
    <joint name="left_front_wheel_joint" type="continuous">
        <parent link="base_link" />
        <child link="left_front_wheel" />
        <origin rpy="0 0 0" xyz="0.35 0.30 0.05" />
        <axis rpy="0 0 0" xyz="0 1 0" />
    </joint>
    <link name="left_rear_wheel">
        <visual>
            <origin rpy="1.570796326795 0 -1.570796326795" xyz="-0.14686986 0 0" />
            <geometry>
                <mesh filename="package://cluerosity_description/meshes/tyre.dae" />
            </geometry>
        </visual>
        <visual>
            <origin rpy="0 0 3.14159265359" xyz="0 0 0" />
            <geometry>
                <mesh filename="package://cluerosity_description/meshes/rim.dae" />
            </geometry>
        </visual>
        <collision>
            <origin rpy="1.570796326795 0 0" xyz="0 0 0" />
            <geometry>
                <cylinder length="0.15" radius="0.165" />
            </geometry>
        </collision>

        <inertial>
            <mass value="5.52250093" />
            <origin rpy="1.570796326795 0 0" xyz="0 0 0" />
            <inertia ixx="0.13326254" ixy="0" ixz="0" iyy="0.07660474" iyz="0" izz="0.077" />
        </inertial>

    </link>
    <joint name="left_rear_wheel_joint" type="continuous">
        <parent link="base_link" />
        <child link="left_rear_wheel" />
        <origin rpy="0 0 0" xyz="-0.20 0.30 0.05" />
        <axis rpy="0 0 0" xyz="0 1 0" />
    </joint>
    <!-- 
        +=====================+
        |   Sensor Gimbal     |
        +=====================+ 
    -->
    <link name="gimbal_base">
        <visual>
            <origin rpy="0 0 0" xyz="0 0 0.025" />
            <geometry>
                <box size="0.1 0.1 0.05" />
            </geometry>
            <material name="dark_gray" />
        </visual>
        <collision>
            <origin rpy="0 0 0" xyz="0 0 0.025" />
            <geometry>
                <box size="0.1 0.1 0.05" />
            </geometry>
        </collision>

        <inertial>
            <mass value="3.4875" />
            <origin rpy="0 0 0" xyz="0 0 0.025" />
            <inertia ixx="0.004" ixy="0" ixz="0" iyy="0.004" iyz="0" izz="0.006" />
        </inertial>

    </link>
    <joint name="gimbal_base_joint" type="fixed">
        <parent link="base_link" />
        <child link="gimbal_base" />
        <origin rpy="0 0 1.570796326795" xyz="0.340 -0.140 0.1" />
    </joint>
    <link name="gimbal_axle">
        <visual>
            <origin rpy="0 0 0" xyz="0 0 0" />
            <geometry>
                <mesh filename="package://cluerosity_description/meshes/gimbal_axle.dae" />
            </geometry>
        </visual>
        <collision>
            <origin rpy="0 0 0" xyz="0 0 0.12" />
            <geometry>
                <box size="0.07 0.07 0.190" />
            </geometry>
        </collision>

        <inertial>
            <mass value="0.86030554" />
            <origin rpy="0 0 0" xyz="0 0 0.12" />
            <inertia ixx="0.00159531" ixy="0" ixz="0" iyy="0.00204855" iyz="0" izz="0.00078318" />
        </inertial>

    </link>
    <joint name="gimbal_axle_joint" type="continuous">
        <!-- change back to "continuous" -->
        <parent link="gimbal_base" />
        <child link="gimbal_axle" />
        <origin rpy="0 0 0" xyz="0 0 0" />
        <axis rpy="0 0 0" xyz="0 0 1" />
    </joint>
    <link name="sensor_housing">
        <visual>
            <origin rpy="0 0 0" xyz="0 0 0.053" />
            <geometry>
                <mesh filename="package://cluerosity_description/meshes/sensor_housing.dae" />
            </geometry>
        </visual>
        <collision>
            <origin rpy="0 0 0" xyz="0 0 0.105" />
            <geometry>
                <box size="0.200 0.100 0.150" />
            </geometry>
        </collision>

        <inertial>
            <mass value="2.14582602" />
            <origin rpy="0 0 0" xyz="0 0 0.105" />
            <inertia ixx="0.00498945" ixy="-2.479e-05" ixz="0.0002252" iyy="0.00883757" iyz="-5.538e-05" izz="0.00675851" />
        </inertial>

    </link>
    <joint name="sensor_housing_joint" type="revolute">
        <!-- change back to "revolute" -->
        <parent link="stepper_motor" />
        <child link="sensor_housing" />
        <origin rpy="0 0 0" xyz="0.122 0 0" />
        <axis rpy="0 0 0" xyz="1 0 0" />
        <limit effort="1000.0" lower="-0.35" upper="0.35" velocity="0.5" />
    </joint>
    <link name="stepper_motor">
        <visual>
            <origin rpy="0 1.570796326795 0" xyz="0 0 0" />
            <geometry>
                <mesh filename="package://cluerosity_description/meshes/stepper_motor.dae" />
            </geometry>
        </visual>
        <collision>
            <origin rpy="0 1.570796326795 0" xyz="0.0325 0 0" />
            <geometry>
                <box size="0.05 0.05 0.080" />
            </geometry>
        </collision>

        <inertial>
            <mass value="0.20879833" />
            <origin rpy="0 1.570796326795 0" xyz="0.0325 0 0" />
            <inertia ixx="9.78e-05" ixy="0" ixz="0" iyy="9.78e-05" iyz="0" izz="4.91e-05" />
        </inertial>

    </link>
    <joint name="stepper_motor_joint" type="fixed">
        <parent link="gimbal_axle" />
        <child link="stepper_motor" />
        <origin rpy="0 0 0" xyz="-0.10 0 0.19" />
    </joint>
    <link name="camera_link">
        <!-- <xacro:box_link 
                xyz="0 0 0" rpy="0 0 0" 
                box_size="0.01 0.01 0.01"
                material_name="dark_gray"/>
            <xacro:box_collision 
                xyz="0 0 0" rpy="0 0 0" 
                box_size="0.01 0.01 0.01"/>
            <xacro:link_inertia 
                xyz="0 0 0" rpy="0 0 0" 
                mass="0.1" 
                ixx="0.004" ixy="0" ixz="0"  
                iyy="0.004" iyz="0"  izz="0.006"/> -->
    </link>
    <joint name="camera_link_joint" type="fixed">
        <parent link="sensor_housing" />
        <child link="camera_link" />
        <origin rpy="0 0 -1.570796326795" xyz="0.035 -0.05 0.125" />
    </joint>
    <link name="camera_depth_link">
        <!-- <xacro:box_link 
                xyz="0 0 0" rpy="0 0 0" 
                box_size="0.01 0.01 0.01"
                material_name="dark_gray"/>
            <xacro:box_collision 
                xyz="0 0 0" rpy="0 0 0" 
                box_size="0.01 0.01 0.01"/>
            <xacro:link_inertia 
                xyz="0 0 0" rpy="0 0 0" 
                mass="0.1" 
                ixx="0.004" ixy="0" ixz="0"  
                iyy="0.004" iyz="0"  izz="0.006"/> -->
    </link>
    <joint name="camera_depth_link_joint" type="fixed">
        <parent link="camera_link" />
        <child link="camera_depth_link" />
        <origin rpy="-1.570796326795 0 -1.570796326795" xyz="0.05 0 0" />
    </joint>
    <link name="hokuyo_link">
        <!-- <xacro:box_link 
                xyz="0 0 0" rpy="0 0 0" 
                box_size="0.01 0.01 0.01"
                material_name="dark_gray"/>
            <xacro:box_collision 
                xyz="0 0 0" rpy="0 0 0" 
                box_size="0.01 0.01 0.01"/>
            <xacro:link_inertia 
                xyz="0 0 0" rpy="0 0 0" 
                mass="0.1" 
                ixx="0.004" ixy="0" ixz="0"  
                iyy="0.004" iyz="0"  izz="0.006"/> -->
    </link>
    <joint name="hokuyo_link_joint" type="fixed">
        <parent link="sensor_housing" />
        <child link="hokuyo_link" />
        <origin rpy="0 0 -1.570796326795" xyz="0.05 -0.05 0.035" />
    </joint>
    <!-- 
        +=======================+
        | Velodyne LiDAR Sensor |
        +=======================+ 
    -->
    <link name="lidar_base">
        <visual>
            <origin rpy="0 3.14159265359 1.570796326795" xyz="-0.075 0 0.05" />
            <geometry>
                <mesh filename="package://cluerosity_description/meshes/lidar_base.dae" />
            </geometry>
        </visual>
        <collision>
            <origin rpy="0 0 0" xyz="-0.135 0 0.025" />
            <geometry>
                <box size="0.270 0.120 0.05" />
            </geometry>
        </collision>

        <inertial>
            <mass value="0.93983878" />
            <origin rpy="0 0 0" xyz="-0.135 0 0.025" />
            <inertia ixx="0.00318358" ixy="0" ixz="0" iyy="0.00133395" iyz="0.00023839" izz="0.0040904" />
        </inertial>

    </link>
    <joint name="lidar_base_joint" type="fixed">
        <parent link="base_link" />
        <child link="lidar_base" />
        <origin rpy="0 0 0" xyz="-0.325 0.140 0.25" />
    </joint>
    <link name="lidar_sensor">
        <visual>
            <origin rpy="0 0 0" xyz="0 0 0" />
            <geometry>
                <mesh filename="package://cluerosity_description/meshes/velodyne_lidar.dae" />
            </geometry>
        </visual>
        <collision>
            <origin rpy="0 0 0" xyz="0 0 0.0375" />
            <geometry>
                <box size="0.105 0.105 0.075" />
            </geometry>
        </collision>

        <inertial>
            <mass value="0.61826506" />
            <origin rpy="0 0 0" xyz="0 0 0.0375" />
            <inertia ixx="0.00067265" ixy="0" ixz="0" iyy="0.0006728" iyz="0" izz="0.00080351" />
        </inertial>

    </link>
    <joint name="lidar_sensor_joint" type="fixed">
        <parent link="lidar_base" />
        <child link="lidar_sensor" />
        <origin rpy="0 0 0" xyz="-0.2 0 0.05" />
    </joint>
    <transmission name="sensor_housing_trans">
        <type>transmission_interface/SimpleTransmission</type>
        <joint name="sensor_housing_joint">
            <hardwareInterface>hardware_interface/EffortJointInterface</hardwareInterface>
        </joint>
        <actuator name="motor7">
            <hardwareInterface>hardware_interface/EffortJointInterface</hardwareInterface>
            <mechanicalInterface>1</mechanicalInterface>
        </actuator>
    </transmission>
    <transmission name="gimbal_axle_trans">
        <type>transmission_interface/SimpleTransmission</type>
        <joint name="gimbal_axle_joint">
            <hardwareInterface>hardware_interface/EffortJointInterface</hardwareInterface>
        </joint>
        <actuator name="motor6">
            <hardwareInterface>hardware_interface/EffortJointInterface</hardwareInterface>
            <mechanicalInterface>1</mechanicalInterface>
        </actuator>
    </transmission>
    <transmission name="motor_01_trans">
        <type>transmission_interface/SimpleTransmission</type>
        <joint name="motor_01_joint">
            <hardwareInterface>hardware_interface/EffortJointInterface</hardwareInterface>
        </joint>
        <actuator name="motor1">
            <hardwareInterface>hardware_interface/EffortJointInterface</hardwareInterface>
            <mechanicalInterface>1</mechanicalInterface>
        </actuator>
    </transmission>
    <transmission name="motor_02_trans">
        <type>transmission_interface/SimpleTransmission</type>
        <joint name="motor_02_joint">
            <hardwareInterface>hardware_interface/EffortJointInterface</hardwareInterface>
        </joint>
        <actuator name="motor2">
            <hardwareInterface>hardware_interface/EffortJointInterface</hardwareInterface>
            <mechanicalInterface>1</mechanicalInterface>
        </actuator>
    </transmission>
    <transmission name="motor_03_trans">
        <type>transmission_interface/SimpleTransmission</type>
        <joint name="motor_03_joint">
            <hardwareInterface>hardware_interface/EffortJointInterface</hardwareInterface>
        </joint>
        <actuator name="motor3">
            <hardwareInterface>hardware_interface/EffortJointInterface</hardwareInterface>
            <mechanicalInterface>1</mechanicalInterface>
        </actuator>
    </transmission>
    <transmission name="motor_04_trans">
        <type>transmission_interface/SimpleTransmission</type>
        <joint name="motor_04_joint">
            <hardwareInterface>hardware_interface/EffortJointInterface</hardwareInterface>
        </joint>
        <actuator name="motor4">
            <hardwareInterface>hardware_interface/EffortJointInterface</hardwareInterface>
            <mechanicalInterface>1</mechanicalInterface>
        </actuator>
    </transmission>
    <transmission name="motor_05_trans">
        <type>transmission_interface/SimpleTransmission</type>
        <joint name="motor_05_joint">
            <hardwareInterface>hardware_interface/EffortJointInterface</hardwareInterface>
        </joint>
        <actuator name="motor5">
            <hardwareInterface>hardware_interface/EffortJointInterface</hardwareInterface>
            <mechanicalInterface>1</mechanicalInterface>
        </actuator>
    </transmission>
    <!-- 
        +=======================+
        |       Manipulator      |
        +=======================+ 
    -->
    <link name="motor_01">
        <visual>
            <origin rpy="0 0 0" xyz="0 0 0" />
            <geometry>
                <mesh filename="package://cluerosity_description/meshes/motor.dae" />
            </geometry>
        </visual>
        <collision>
            <origin rpy="0 0 0" xyz="0 0 0" />
            <geometry>
                <box size="0.065 0.065 0.1" />
            </geometry>
        </collision>

        <inertial>
            <mass value="0.33104028" />
            <origin rpy="0 0 0" xyz="0 0 0" />
            <inertia ixx="0.00022976" ixy="0" ixz="0" iyy="0.00022976" iyz="0" izz="0.00011672" />
        </inertial>

    </link>
    <joint name="motor_01_joint" type="revolute">
        <parent link="base_link" />
        <child link="motor_01" />
        <origin rpy="3.14159265359 0 0" xyz="0.498 0.15 0.09" />
        <axis rpy="0 0 0" xyz="0 0 1" />
        <limit effort="1000.0" lower="-0.3" upper="1.2" velocity="0.5" />
        --&gt;
    </joint>
    <link name="motor_connector_01">
        <visual>
            <origin rpy="0 0 0" xyz="0 0 0" />
            <geometry>
                <mesh filename="package://cluerosity_description/meshes/motor_connector_01.dae" />
            </geometry>
        </visual>
        <collision>
            <origin rpy="0 0 0" xyz="0 0 0" />
            <geometry>
                <box size="0.05 0.05 0.05" />
            </geometry>
        </collision>

        <inertial>
            <mass value="0.1226583" />
            <origin rpy="0 0 0" xyz="0 0 0" />
            <inertia ixx="6.619e-05" ixy="0" ixz="0" iyy="7.979e-05" iyz="0" izz="6.619e-05" />
        </inertial>

    </link>
    <joint name="motor_connector_01_joint" type="fixed">
        <parent link="motor_01" />
        <child link="motor_connector_01" />
        <origin rpy="1.570796326795 1.570796326795 0" xyz="0.046 0 0.0395" />
    </joint>
    <link name="motor_02">
        <visual>
            <origin rpy="0 0 0" xyz="0 0 0" />
            <geometry>
                <mesh filename="package://cluerosity_description/meshes/motor.dae" />
            </geometry>
        </visual>
        <collision>
            <origin rpy="0 0 0" xyz="0 0 0" />
            <geometry>
                <box size="0.065 0.065 0.1" />
            </geometry>
        </collision>

        <inertial>
            <mass value="0.33104028" />
            <origin rpy="0 0 0" xyz="0 0 0" />
            <inertia ixx="0.00022976" ixy="0" ixz="0" iyy="0.00022976" iyz="0" izz="0.00011672" />
        </inertial>

    </link>
    <joint name="motor_02_joint" type="revolute">
        <parent link="motor_connector_01" />
        <child link="motor_02" />
        <origin rpy="0 0 0" xyz="0 0.036 -0.0395" />
        <axis rpy="0 0 0" xyz="0 0 1" />
        <limit effort="1000.0" lower="-1.570796326795" upper="0" velocity="0.5" />
        --&gt;
    </joint>
    <link name="link_01">
        <visual>
            <origin rpy="0 0 0" xyz="0 0 0" />
            <geometry>
                <mesh filename="package://cluerosity_description/meshes/link_01.dae" />
            </geometry>
        </visual>
        <collision>
            <origin rpy="0 0 0" xyz="0 -0.180 0" />
            <geometry>
                <box size="0.06 0.36 0.06" />
            </geometry>
        </collision>

        <inertial>
            <mass value="1.28482853" />
            <origin rpy="0 0 0" xyz="0 -0.180 0" />
            <inertia ixx="0.01710143" ixy="0" ixz="0" iyy="0.00045593" iyz="0" izz="0.01705674" />
        </inertial>

    </link>
    <joint name="link_01_joint" type="fixed">
        <parent link="motor_02" />
        <child link="link_01" />
        <origin rpy="0 0 3.14159265359" xyz="0 0 0" />
    </joint>
    <link name="motor_03">
        <visual>
            <origin rpy="0 0 0" xyz="0 0 0" />
            <geometry>
                <mesh filename="package://cluerosity_description/meshes/motor.dae" />
            </geometry>
        </visual>
        <collision>
            <origin rpy="0 0 0" xyz="0 0 0" />
            <geometry>
                <box size="0.065 0.065 0.1" />
            </geometry>
        </collision>

        <inertial>
            <mass value="0.33104028" />
            <origin rpy="0 0 0" xyz="0 0 0" />
            <inertia ixx="0.00022976" ixy="0" ixz="0" iyy="0.00022976" iyz="0" izz="0.00011672" />
        </inertial>

    </link>
    <joint name="motor_03_joint" type="revolute">
        <parent link="link_01" />
        <child link="motor_03" />
        <origin rpy="0 0 0" xyz="0 -0.35 0" />
        <axis rpy="0 0 0" xyz="0 0 1" />
        <limit effort="1000.0" lower="0" upper="1.570796326795" velocity="0.5" />
        --&gt;
    </joint>
    <link name="link_02">
        <visual>
            <origin rpy="0 0 0" xyz="0 0 0" />
            <geometry>
                <mesh filename="package://cluerosity_description/meshes/link_02.dae" />
            </geometry>
        </visual>
        <collision>
            <origin rpy="0 0 0" xyz="0.180 0 0" />
            <geometry>
                <box size="0.36 0.06 0.06" />
            </geometry>
        </collision>

        <inertial>
            <mass value="1.19702377" />
            <origin rpy="0 0 0" xyz="0.180 0 0" />
            <inertia ixx="0.00043777" ixy="8.65e-06" ixz="0" iyy="0.01364495" iyz="0" izz="0.01375154" />
        </inertial>

    </link>
    <joint name="link_02_joint" type="fixed">
        <parent link="motor_03" />
        <child link="link_02" />
        <origin rpy="0 0 3.14159265359" xyz="0 0 0.0395" />
    </joint>
    <link name="motor_04">
        <visual>
            <origin rpy="0 0 0" xyz="0 0 0" />
            <geometry>
                <mesh filename="package://cluerosity_description/meshes/motor.dae" />
            </geometry>
        </visual>
        <collision>
            <origin rpy="0 0 0" xyz="0 0 0" />
            <geometry>
                <box size="0.065 0.065 0.1" />
            </geometry>
        </collision>

        <inertial>
            <mass value="0.33104028" />
            <origin rpy="0 0 0" xyz="0 0 0" />
            <inertia ixx="0.00022976" ixy="0" ixz="0" iyy="0.00022976" iyz="0" izz="0.00011672" />
        </inertial>

    </link>
    <joint name="motor_04_joint" type="revolute">
        <parent link="link_02" />
        <child link="motor_04" />
        <origin rpy="0 0 0" xyz="0.370 0 -0.0395" />
        <axis rpy="0 0 0" xyz="0 0 1" />
        <limit effort="1000.0" lower="-1.570796326795" upper="1.570796326795" velocity="0.5" />
        --&gt;
    </joint>
    <link name="motor_connector_02">
        <visual>
            <origin rpy="0 0 0" xyz="0 0 0" />
            <geometry>
                <mesh filename="package://cluerosity_description/meshes/motor_connector_02.dae" />
            </geometry>
        </visual>
        <collision>
            <origin rpy="0 0 0" xyz="0 0 0" />
            <geometry>
                <box size="0.05 0.05 0.05" />
            </geometry>
        </collision>

        <inertial>
            <mass value="0.32771971" />
            <origin rpy="0 0 0" xyz="0 0 0" />
            <inertia ixx="0.00031006" ixy="0" ixz="0" iyy="0.00083377" iyz="0" izz="0.00055215" />
        </inertial>

    </link>
    <joint name="motor_connector_02_joint" type="fixed">
        <parent link="motor_04" />
        <child link="motor_connector_02" />
        <origin rpy="0 0 0" xyz="0 0 0" />
    </joint>
    <link name="motor_05">
        <visual>
            <origin rpy="0 0 0" xyz="0 0 0" />
            <geometry>
                <mesh filename="package://cluerosity_description/meshes/motor.dae" />
            </geometry>
        </visual>
        <collision>
            <origin rpy="0 0 0" xyz="0 0 0" />
            <geometry>
                <box size="0.05 0.05 0.15" />
            </geometry>
        </collision>

        <inertial>
            <mass value="0.61826506" />
            <origin rpy="0 0 0" xyz="0 0 0" />
            <inertia ixx="0.00067265" ixy="0" ixz="0" iyy="0.0006728" iyz="0" izz="0.00080351" />
        </inertial>

    </link>
    <joint name="motor_05_joint" type="continuous">
        <parent link="motor_connector_02" />
        <child link="motor_05" />
        <origin rpy="0 -1.570796326795 0" xyz="0.1395 0 0.1" />
        <axis rpy="0 0 0" xyz="0 0 1" />
    </joint>
    <link name="end_effector_connector">
        <visual>
            <origin rpy="0 0 0" xyz="0 0 0" />
            <geometry>
                <mesh filename="package://cluerosity_description/meshes/end_effector_connector.dae" />
            </geometry>
        </visual>
        <collision>
            <origin rpy="0 0 0" xyz="0 0 0" />
            <geometry>
                <box size="0.105 0.105 0.075" />
            </geometry>
        </collision>

        <inertial>
            <mass value="0.30502898" />
            <origin rpy="0 0 0" xyz="0 0 0" />
            <inertia ixx="0.00027224" ixy="0" ixz="0" iyy="0.00042032" iyz="0" izz="0.00020714" />
        </inertial>

    </link>
    <joint name="end_effector_connector_joint" type="fixed">
        <parent link="motor_05" />
        <child link="end_effector_connector" />
        <origin rpy="0 0 -1.570796326795" xyz="0 0 0" />
    </joint>
    <transmission name="trans_right_front_wheel_joint">
        <type>transmission_interface/SimpleTransmission</type>
        <joint name="right_front_wheel_joint">
            <hardwareInterface>hardware_interface/EffortJointInterface</hardwareInterface>
        </joint>
        <actuator name="right_front_wheel_joint_motor">
            <hardwareInterface>hardware_interface/EffortJointInterface</hardwareInterface>
            <mechanicalReduction>1</mechanicalReduction>
        </actuator>
    </transmission>
    <transmission name="trans_right_rear_wheel_joint">
        <type>transmission_interface/SimpleTransmission</type>
        <joint name="right_rear_wheel_joint">
            <hardwareInterface>hardware_interface/EffortJointInterface</hardwareInterface>
        </joint>
        <actuator name="right_rear_wheel_joint_motor">
            <hardwareInterface>hardware_interface/EffortJointInterface</hardwareInterface>
            <mechanicalReduction>1</mechanicalReduction>
        </actuator>
    </transmission>
    <transmission name="trans_left_front_wheel_joint">
        <type>transmission_interface/SimpleTransmission</type>
        <joint name="left_front_wheel_joint">
            <hardwareInterface>hardware_interface/EffortJointInterface</hardwareInterface>
        </joint>
        <actuator name="left_front_wheel_joint_motor">
            <hardwareInterface>hardware_interface/EffortJointInterface</hardwareInterface>
            <mechanicalReduction>1</mechanicalReduction>
        </actuator>
    </transmission>
    <transmission name="trans_left_rear_wheel_joint">
        <type>transmission_interface/SimpleTransmission</type>
        <joint name="left_rear_wheel_joint">
            <hardwareInterface>hardware_interface/EffortJointInterface</hardwareInterface>
        </joint>
        <actuator name="left_rear_wheel_joint_motor">
            <hardwareInterface>hardware_interface/EffortJointInterface</hardwareInterface>
            <mechanicalReduction>1</mechanicalReduction>
        </actuator>
    </transmission>
    <transmission name="trans_gimbal_axle_joint">
        <type>transmission_interface/SimpleTransmission</type>
        <joint name="gimbal_axle_joint">
            <hardwareInterface>hardware_interface/EffortJointInterface</hardwareInterface>
        </joint>
        <actuator name="gimbal_axle_joint_motor">
            <hardwareInterface>hardware_interface/EffortJointInterface</hardwareInterface>
            <mechanicalReduction>1</mechanicalReduction>
        </actuator>
    </transmission>
    <transmission name="trans_sensor_housing_joint">
        <type>transmission_interface/SimpleTransmission</type>
        <joint name="sensor_housing_joint">
            <hardwareInterface>hardware_interface/EffortJointInterface</hardwareInterface>
        </joint>
        <actuator name="sensor_housing_joint_motor">
            <hardwareInterface>hardware_interface/EffortJointInterface</hardwareInterface>
            <mechanicalReduction>1</mechanicalReduction>
        </actuator>
    </transmission>
    <transmission name="trans_motor_01_joint">
        <type>transmission_interface/SimpleTransmission</type>
        <joint name="motor_01_joint">
            <hardwareInterface>hardware_interface/EffortJointInterface</hardwareInterface>
        </joint>
        <actuator name="motor_01_joint_motor">
            <hardwareInterface>hardware_interface/EffortJointInterface</hardwareInterface>
            <mechanicalReduction>1</mechanicalReduction>
        </actuator>
    </transmission>
    <transmission name="trans_motor_02_joint">
        <type>transmission_interface/SimpleTransmission</type>
        <joint name="motor_02_joint">
            <hardwareInterface>hardware_interface/EffortJointInterface</hardwareInterface>
        </joint>
        <actuator name="motor_02_joint_motor">
            <hardwareInterface>hardware_interface/EffortJointInterface</hardwareInterface>
            <mechanicalReduction>1</mechanicalReduction>
        </actuator>
    </transmission>
    <transmission name="trans_motor_03_joint">
        <type>transmission_interface/SimpleTransmission</type>
        <joint name="motor_03_joint">
            <hardwareInterface>hardware_interface/EffortJointInterface</hardwareInterface>
        </joint>
        <actuator name="motor_03_joint_motor">
            <hardwareInterface>hardware_interface/EffortJointInterface</hardwareInterface>
            <mechanicalReduction>1</mechanicalReduction>
        </actuator>
    </transmission>
    <transmission name="trans_motor_04_joint">
        <type>transmission_interface/SimpleTransmission</type>
        <joint name="motor_04_joint">
            <hardwareInterface>hardware_interface/EffortJointInterface</hardwareInterface>
        </joint>
        <actuator name="motor_04_joint_motor">
            <hardwareInterface>hardware_interface/EffortJointInterface</hardwareInterface>
            <mechanicalReduction>1</mechanicalReduction>
        </actuator>
    </transmission>
    <transmission name="trans_motor_05_joint">
        <type>transmission_interface/SimpleTransmission</type>
        <joint name="motor_05_joint">
            <hardwareInterface>hardware_interface/EffortJointInterface</hardwareInterface>
        </joint>
        <actuator name="motor_05_joint_motor">
            <hardwareInterface>hardware_interface/EffortJointInterface</hardwareInterface>
            <mechanicalReduction>1</mechanicalReduction>
        </actuator>
    </transmission>
    <gazebo>
        <plugin name="gazebo_ros_control" filename="libgazebo_ros_control.so">
            <robotNamespace>/</robotNamespace>
        </plugin>
    </gazebo>

    <transmission name="sensor_housing_trans">
        <type>transmission_interface/SimpleTransmission</type>
        <joint name="sensor_housing_joint">
            <hardwareInterface>hardware_interface/EffortJointInterface</hardwareInterface>
        </joint>
        <actuator name="motor7">
            <hardwareInterface>hardware_interface/EffortJointInterface</hardwareInterface>
            <mechanicalInterface>1</mechanicalInterface>
        </actuator>
    </transmission>
    <transmission name="gimbal_axle_trans">
        <type>transmission_interface/SimpleTransmission</type>
        <joint name="gimbal_axle_joint">
            <hardwareInterface>hardware_interface/EffortJointInterface</hardwareInterface>
        </joint>
        <actuator name="motor6">
            <hardwareInterface>hardware_interface/EffortJointInterface</hardwareInterface>
            <mechanicalInterface>1</mechanicalInterface>
        </actuator>
    </transmission>
    <transmission name="motor_01_trans">
        <type>transmission_interface/SimpleTransmission</type>
        <joint name="motor_01_joint">
            <hardwareInterface>hardware_interface/EffortJointInterface</hardwareInterface>
        </joint>
        <actuator name="motor1">
            <hardwareInterface>hardware_interface/EffortJointInterface</hardwareInterface>
            <mechanicalInterface>1</mechanicalInterface>
        </actuator>
    </transmission>
    <transmission name="motor_02_trans">
        <type>transmission_interface/SimpleTransmission</type>
        <joint name="motor_02_joint">
            <hardwareInterface>hardware_interface/EffortJointInterface</hardwareInterface>
        </joint>
        <actuator name="motor2">
            <hardwareInterface>hardware_interface/EffortJointInterface</hardwareInterface>
            <mechanicalInterface>1</mechanicalInterface>
        </actuator>
    </transmission>
    <transmission name="motor_03_trans">
        <type>transmission_interface/SimpleTransmission</type>
        <joint name="motor_03_joint">
            <hardwareInterface>hardware_interface/EffortJointInterface</hardwareInterface>
        </joint>
        <actuator name="motor3">
            <hardwareInterface>hardware_interface/EffortJointInterface</hardwareInterface>
            <mechanicalInterface>1</mechanicalInterface>
        </actuator>
    </transmission>
    <transmission name="motor_04_trans">
        <type>transmission_interface/SimpleTransmission</type>
        <joint name="motor_04_joint">
            <hardwareInterface>hardware_interface/EffortJointInterface</hardwareInterface>
        </joint>
        <actuator name="motor4">
            <hardwareInterface>hardware_interface/EffortJointInterface</hardwareInterface>
            <mechanicalInterface>1</mechanicalInterface>
        </actuator>
    </transmission>
    <transmission name="motor_05_trans">
        <type>transmission_interface/SimpleTransmission</type>
        <joint name="motor_05_joint">
            <hardwareInterface>hardware_interface/EffortJointInterface</hardwareInterface>
        </joint>
        <actuator name="motor5">
            <hardwareInterface>hardware_interface/EffortJointInterface</hardwareInterface>
            <mechanicalInterface>1</mechanicalInterface>
        </actuator>
    </transmission>
    <!-- 
        +=======================+
        |       Manipulator      |
        +=======================+ 
    -->
    <link name="motor_01">
        <visual>
            <origin rpy="0 0 0" xyz="0 0 0" />
            <geometry>
                <mesh filename="package://cluerosity_description/meshes/motor.dae" />
            </geometry>
        </visual>
        <collision>
            <origin rpy="0 0 0" xyz="0 0 0" />
            <geometry>
                <box size="0.065 0.065 0.1" />
            </geometry>
        </collision>
        <inertial>
            <mass value="0.33104028" />
            <origin rpy="0 0 0" xyz="0 0 0" />
            <inertia ixx="0.00022976" ixy="0" ixz="0" iyy="0.00022976" iyz="0" izz="0.00011672" />
        </inertial>
    </link>
    <joint name="motor_01_joint" type="revolute">
        <parent link="base_link" />
        <child link="motor_01" />
        <origin rpy="3.14159265359 0 0" xyz="0.498 0.15 0.09" />
        <axis rpy="0 0 0" xyz="0 0 1" />
        <limit effort="1000.0" lower="-0.3" upper="1.2" velocity="0.5" />
        --&gt;
    </joint>
    <link name="motor_connector_01">
        <visual>
            <origin rpy="0 0 0" xyz="0 0 0" />
            <geometry>
                <mesh filename="package://cluerosity_description/meshes/motor_connector_01.dae" />
            </geometry>
        </visual>
        <collision>
            <origin rpy="0 0 0" xyz="0 0 0" />
            <geometry>
                <box size="0.05 0.05 0.05" />
            </geometry>
        </collision>
        <inertial>
            <mass value="0.1226583" />
            <origin rpy="0 0 0" xyz="0 0 0" />
            <inertia ixx="6.619e-05" ixy="0" ixz="0" iyy="7.979e-05" iyz="0" izz="6.619e-05" />
        </inertial>
    </link>
    <joint name="motor_connector_01_joint" type="fixed">
        <parent link="motor_01" />
        <child link="motor_connector_01" />
        <origin rpy="1.570796326795 1.570796326795 0" xyz="0.046 0 0.0395" />
    </joint>
    <link name="motor_02">
        <visual>
            <origin rpy="0 0 0" xyz="0 0 0" />
            <geometry>
                <mesh filename="package://cluerosity_description/meshes/motor.dae" />
            </geometry>
        </visual>
        <collision>
            <origin rpy="0 0 0" xyz="0 0 0" />
            <geometry>
                <box size="0.065 0.065 0.1" />
            </geometry>
        </collision>
        <inertial>
            <mass value="0.33104028" />
            <origin rpy="0 0 0" xyz="0 0 0" />
            <inertia ixx="0.00022976" ixy="0" ixz="0" iyy="0.00022976" iyz="0" izz="0.00011672" />
        </inertial>
    </link>
    <joint name="motor_02_joint" type="revolute">
        <parent link="motor_connector_01" />
        <child link="motor_02" />
        <origin rpy="0 0 0" xyz="0 0.036 -0.0395" />
        <axis rpy="0 0 0" xyz="0 0 1" />
        <limit effort="1000.0" lower="-1.570796326795" upper="0" velocity="0.5" />
        --&gt;
    </joint>
    <link name="link_01">
        <visual>
            <origin rpy="0 0 0" xyz="0 0 0" />
            <geometry>
                <mesh filename="package://cluerosity_description/meshes/link_01.dae" />
            </geometry>
        </visual>
        <collision>
            <origin rpy="0 0 0" xyz="0 -0.180 0" />
            <geometry>
                <box size="0.06 0.36 0.06" />
            </geometry>
        </collision>
        <inertial>
            <mass value="1.28482853" />
            <origin rpy="0 0 0" xyz="0 -0.180 0" />
            <inertia ixx="0.01710143" ixy="0" ixz="0" iyy="0.00045593" iyz="0" izz="0.01705674" />
        </inertial>
    </link>
    <joint name="link_01_joint" type="fixed">
        <parent link="motor_02" />
        <child link="link_01" />
        <origin rpy="0 0 3.14159265359" xyz="0 0 0" />
    </joint>
    <link name="motor_03">
        <visual>
            <origin rpy="0 0 0" xyz="0 0 0" />
            <geometry>
                <mesh filename="package://cluerosity_description/meshes/motor.dae" />
            </geometry>
        </visual>
        <collision>
            <origin rpy="0 0 0" xyz="0 0 0" />
            <geometry>
                <box size="0.065 0.065 0.1" />
            </geometry>
        </collision>
        <inertial>
            <mass value="0.33104028" />
            <origin rpy="0 0 0" xyz="0 0 0" />
            <inertia ixx="0.00022976" ixy="0" ixz="0" iyy="0.00022976" iyz="0" izz="0.00011672" />
        </inertial>
    </link>
    <joint name="motor_03_joint" type="revolute">
        <parent link="link_01" />
        <child link="motor_03" />
        <origin rpy="0 0 0" xyz="0 -0.35 0" />
        <axis rpy="0 0 0" xyz="0 0 1" />
        <limit effort="1000.0" lower="0" upper="1.570796326795" velocity="0.5" />
        --&gt;
    </joint>
    <link name="link_02">
        <visual>
            <origin rpy="0 0 0" xyz="0 0 0" />
            <geometry>
                <mesh filename="package://cluerosity_description/meshes/link_02.dae" />
            </geometry>
        </visual>
        <collision>
            <origin rpy="0 0 0" xyz="0.180 0 0" />
            <geometry>
                <box size="0.36 0.06 0.06" />
            </geometry>
        </collision>
        <inertial>
            <mass value="1.19702377" />
            <origin rpy="0 0 0" xyz="0.180 0 0" />
            <inertia ixx="0.00043777" ixy="8.65e-06" ixz="0" iyy="0.01364495" iyz="0" izz="0.01375154" />
        </inertial>
    </link>
    <joint name="link_02_joint" type="fixed">
        <parent link="motor_03" />
        <child link="link_02" />
        <origin rpy="0 0 3.14159265359" xyz="0 0 0.0395" />
    </joint>
    <link name="motor_04">
        <visual>
            <origin rpy="0 0 0" xyz="0 0 0" />
            <geometry>
                <mesh filename="package://cluerosity_description/meshes/motor.dae" />
            </geometry>
        </visual>
        <collision>
            <origin rpy="0 0 0" xyz="0 0 0" />
            <geometry>
                <box size="0.065 0.065 0.1" />
            </geometry>
        </collision>
        <inertial>
            <mass value="0.33104028" />
            <origin rpy="0 0 0" xyz="0 0 0" />
            <inertia ixx="0.00022976" ixy="0" ixz="0" iyy="0.00022976" iyz="0" izz="0.00011672" />
        </inertial>
    </link>
    <joint name="motor_04_joint" type="revolute">
        <parent link="link_02" />
        <child link="motor_04" />
        <origin rpy="0 0 0" xyz="0.370 0 -0.0395" />
        <axis rpy="0 0 0" xyz="0 0 1" />
        <limit effort="1000.0" lower="-1.570796326795" upper="1.570796326795" velocity="0.5" />
        --&gt;
    </joint>
    <link name="motor_connector_02">
        <visual>
            <origin rpy="0 0 0" xyz="0 0 0" />
            <geometry>
                <mesh filename="package://cluerosity_description/meshes/motor_connector_02.dae" />
            </geometry>
        </visual>
        <collision>
            <origin rpy="0 0 0" xyz="0 0 0" />
            <geometry>
                <box size="0.05 0.05 0.05" />
            </geometry>
        </collision>
        <inertial>
            <mass value="0.32771971" />
            <origin rpy="0 0 0" xyz="0 0 0" />
            <inertia ixx="0.00031006" ixy="0" ixz="0" iyy="0.00083377" iyz="0" izz="0.00055215" />
        </inertial>
    </link>
    <joint name="motor_connector_02_joint" type="fixed">
        <parent link="motor_04" />
        <child link="motor_connector_02" />
        <origin rpy="0 0 0" xyz="0 0 0" />
    </joint>
    <link name="motor_05">
        <visual>
            <origin rpy="0 0 0" xyz="0 0 0" />
            <geometry>
                <mesh filename="package://cluerosity_description/meshes/motor.dae" />
            </geometry>
        </visual>
        <collision>
            <origin rpy="0 0 0" xyz="0 0 0" />
            <geometry>
                <box size="0.05 0.05 0.15" />
            </geometry>
        </collision>
        <inertial>
            <mass value="0.61826506" />
            <origin rpy="0 0 0" xyz="0 0 0" />
            <inertia ixx="0.00067265" ixy="0" ixz="0" iyy="0.0006728" iyz="0" izz="0.00080351" />
        </inertial>
    </link>
    <joint name="motor_05_joint" type="continuous">
        <parent link="motor_connector_02" />
        <child link="motor_05" />
        <origin rpy="0 -1.570796326795 0" xyz="0.1395 0 0.1" />
        <axis rpy="0 0 0" xyz="0 0 1" />
    </joint>
    <link name="end_effector_connector">
        <visual>
            <origin rpy="0 0 0" xyz="0 0 0" />
            <geometry>
                <mesh filename="package://cluerosity_description/meshes/end_effector_connector.dae" />
            </geometry>
        </visual>
        <collision>
            <origin rpy="0 0 0" xyz="0 0 0" />
            <geometry>
                <box size="0.105 0.105 0.075" />
            </geometry>
        </collision>
        <inertial>
            <mass value="0.30502898" />
            <origin rpy="0 0 0" xyz="0 0 0" />
            <inertia ixx="0.00027224" ixy="0" ixz="0" iyy="0.00042032" iyz="0" izz="0.00020714" />
        </inertial>
    </link>
    <joint name="end_effector_connector_joint" type="fixed">
        <parent link="motor_05" />
        <child link="end_effector_connector" />
        <origin rpy="0 0 -1.570796326795" xyz="0 0 0" />
    </joint>
    <transmission name="trans_right_front_wheel_joint">
        <type>transmission_interface/SimpleTransmission</type>
        <joint name="right_front_wheel_joint">
            <hardwareInterface>hardware_interface/EffortJointInterface</hardwareInterface>
        </joint>
        <actuator name="right_front_wheel_joint_motor">
            <hardwareInterface>hardware_interface/EffortJointInterface</hardwareInterface>
            <mechanicalReduction>1</mechanicalReduction>
        </actuator>
    </transmission>
    <transmission name="trans_right_rear_wheel_joint">
        <type>transmission_interface/SimpleTransmission</type>
        <joint name="right_rear_wheel_joint">
            <hardwareInterface>hardware_interface/EffortJointInterface</hardwareInterface>
        </joint>
        <actuator name="right_rear_wheel_joint_motor">
            <hardwareInterface>hardware_interface/EffortJointInterface</hardwareInterface>
            <mechanicalReduction>1</mechanicalReduction>
        </actuator>
    </transmission>
    <transmission name="trans_left_front_wheel_joint">
        <type>transmission_interface/SimpleTransmission</type>
        <joint name="left_front_wheel_joint">
            <hardwareInterface>hardware_interface/EffortJointInterface</hardwareInterface>
        </joint>
        <actuator name="left_front_wheel_joint_motor">
            <hardwareInterface>hardware_interface/EffortJointInterface</hardwareInterface>
            <mechanicalReduction>1</mechanicalReduction>
        </actuator>
    </transmission>
    <transmission name="trans_left_rear_wheel_joint">
        <type>transmission_interface/SimpleTransmission</type>
        <joint name="left_rear_wheel_joint">
            <hardwareInterface>hardware_interface/EffortJointInterface</hardwareInterface>
        </joint>
        <actuator name="left_rear_wheel_joint_motor">
            <hardwareInterface>hardware_interface/EffortJointInterface</hardwareInterface>
            <mechanicalReduction>1</mechanicalReduction>
        </actuator>
    </transmission>
    <transmission name="trans_gimbal_axle_joint">
        <type>transmission_interface/SimpleTransmission</type>
        <joint name="gimbal_axle_joint">
            <hardwareInterface>hardware_interface/EffortJointInterface</hardwareInterface>
        </joint>
        <actuator name="gimbal_axle_joint_motor">
            <hardwareInterface>hardware_interface/EffortJointInterface</hardwareInterface>
            <mechanicalReduction>1</mechanicalReduction>
        </actuator>
    </transmission>
    <transmission name="trans_sensor_housing_joint">
        <type>transmission_interface/SimpleTransmission</type>
        <joint name="sensor_housing_joint">
            <hardwareInterface>hardware_interface/EffortJointInterface</hardwareInterface>
        </joint>
        <actuator name="sensor_housing_joint_motor">
            <hardwareInterface>hardware_interface/EffortJointInterface</hardwareInterface>
            <mechanicalReduction>1</mechanicalReduction>
        </actuator>
    </transmission>
    <transmission name="trans_motor_01_joint">
        <type>transmission_interface/SimpleTransmission</type>
        <joint name="motor_01_joint">
            <hardwareInterface>hardware_interface/EffortJointInterface</hardwareInterface>
        </joint>
        <actuator name="motor_01_joint_motor">
            <hardwareInterface>hardware_interface/EffortJointInterface</hardwareInterface>
            <mechanicalReduction>1</mechanicalReduction>
        </actuator>
    </transmission>
    <transmission name="trans_motor_02_joint">
        <type>transmission_interface/SimpleTransmission</type>
        <joint name="motor_02_joint">
            <hardwareInterface>hardware_interface/EffortJointInterface</hardwareInterface>
        </joint>
        <actuator name="motor_02_joint_motor">
            <hardwareInterface>hardware_interface/EffortJointInterface</hardwareInterface>
            <mechanicalReduction>1</mechanicalReduction>
        </actuator>
    </transmission>
    <transmission name="trans_motor_03_joint">
        <type>transmission_interface/SimpleTransmission</type>
        <joint name="motor_03_joint">
            <hardwareInterface>hardware_interface/EffortJointInterface</hardwareInterface>
        </joint>
        <actuator name="motor_03_joint_motor">
            <hardwareInterface>hardware_interface/EffortJointInterface</hardwareInterface>
            <mechanicalReduction>1</mechanicalReduction>
        </actuator>
    </transmission>
    <transmission name="trans_motor_04_joint">
        <type>transmission_interface/SimpleTransmission</type>
        <joint name="motor_04_joint">
            <hardwareInterface>hardware_interface/EffortJointInterface</hardwareInterface>
        </joint>
        <actuator name="motor_04_joint_motor">
            <hardwareInterface>hardware_interface/EffortJointInterface</hardwareInterface>
            <mechanicalReduction>1</mechanicalReduction>
        </actuator>
    </transmission>
    <transmission name="trans_motor_05_joint">
        <type>transmission_interface/SimpleTransmission</type>
        <joint name="motor_05_joint">
            <hardwareInterface>hardware_interface/EffortJointInterface</hardwareInterface>
        </joint>
        <actuator name="motor_05_joint_motor">
            <hardwareInterface>hardware_interface/EffortJointInterface</hardwareInterface>
            <mechanicalReduction>1</mechanicalReduction>
        </actuator>
    </transmission>
    <gazebo>
        <plugin name="gazebo_ros_control" filename="libgazebo_ros_control.so">
            <robotNamespace>/</robotNamespace>
        </plugin>
    </gazebo>
</robot>