<?xml version="1.0"?>
<robot name="cluerosity" xmlns:xacro="http://www.ros.org/wiki/xacro">

    <link name="base_link">
        <visual>
            <origin rpy="0 0 0" xyz="0 0 0.1" />
            <geometry>
                <box size="0.6 0.4 0.2" />
            </geometry>
            <material name="cyan">
                <color rgba="0 1.0 1.0 1.0" />
            </material>
        </visual>
    </link>

    <!-- Base footprint is on the ground under the robot -->
    <link name="base_footprint" />

    <joint name="base_footprint_joint" type="fixed">
        <origin xyz="0 0 -0.14" rpy="0 0 0" />
        <parent link="base_link" />
        <child link="base_footprint" />
    </joint>

    <!-- Wheel definition -->

    <!-- RIGHT WHEEL  -->
    <link name="right_front_wheel">
        <visual>
            <origin xyz="0 0 0" rpy="1.5708 0 0" />
            <geometry>
                <cylinder radius="0.175" length="0.15" />
            </geometry>
            <material name="black">
                <color rgba="0 0 0 1" />
            </material>
        </visual>
    </link>

    <joint name="right_front_wheel_joint" type="continuous">
        <parent link="base_link" />
        <child link="right_front_wheel" />
        <origin xyz="0.3 -0.30 0.045" rpy="0 0 0" />
        <axis xyz="0 1 0" rpy="0 0 0" />
    </joint>

    <link name="right_back_wheel">
        <visual>
            <origin xyz="0 0 0" rpy="1.5708 0 0" />
            <geometry>
                <cylinder radius="0.175" length="0.15" />
            </geometry>
            <material name="black">
                <color rgba="0 0 0 1" />
            </material>
        </visual>
    </link>

    <joint name="right_back_wheel_joint" type="continuous">
        <parent link="base_link" />
        <child link="right_back_wheel" />
        <origin xyz="-0.3 -0.30 0.045" rpy="0 0 0" />
        <axis xyz="0 1 0" rpy="0 0 0" />
    </joint>

    <!-- LEFT WHEEL -->

    <link name="left_front_wheel">
        <visual>
            <origin xyz="0 0 0" rpy="1.5708 0 0" />
            <geometry>
                <cylinder radius="0.175" length="0.15" />
            </geometry>
            <material name="black">
                <color rgba="0 0 0 1" />
            </material>
        </visual>
    </link>

    <joint name="left_front_wheel_joint" type="continuous">
        <parent link="base_link" />
        <child link="left_front_wheel" />
        <origin xyz="0.3 0.30 0.045" rpy="0 0 0" />
        <axis xyz="0 1 0" rpy="0 0 0" />
    </joint>

    <link name="left_back_wheel">
        <visual>
            <origin xyz="0 0 0" rpy="1.5708 0 0" />
            <geometry>
                <cylinder radius="0.175" length="0.15" />
            </geometry>
            <material name="black">
                <color rgba="0 0 0 1" />
            </material>
        </visual>
    </link>

    <joint name="left_back_wheel_joint" type="continuous">
        <parent link="base_link" />
        <child link="left_back_wheel" />
        <origin xyz="-0.3 0.30 0.045" rpy="0 0 0" />
        <axis xyz="0 1 0" rpy="0 0 0" />
    </joint>

</robot>